TITLE:
funny error messages in client

LABEL:
c:misc

STATE:
closed

BODY:
I think the internet may have gone out here?

```
Iteration: 4700. Loss: 0.28484979271888733. Accuracy: 87.02
Iteration: 4800. Loss: 0.3668113350868225. Accuracy: 87.2
Exception in thread Thread-59:
Traceback (most recent call last):
  File "/Users/l2k/.pyenv/versions/3.6.1/envs/wandb-3.6.1/lib/python3.6/site-packages/urllib3/connectionpool.py", line 601, in urlopen
    chunked=chunked)
  File "/Users/l2k/.pyenv/versions/3.6.1/envs/wandb-3.6.1/lib/python3.6/site-packages/urllib3/connectionpool.py", line 346, in _make_request
    self._validate_conn(conn)
  File "/Users/l2k/.pyenv/versions/3.6.1/envs/wandb-3.6.1/lib/python3.6/site-packages/urllib3/connectionpool.py", line 850, in _validate_conn
    conn.connect()
  File "/Users/l2k/.pyenv/versions/3.6.1/envs/wandb-3.6.1/lib/python3.6/site-packages/urllib3/connection.py", line 326, in connect
    ssl_context=context)
  File "/Users/l2k/.pyenv/versions/3.6.1/envs/wandb-3.6.1/lib/python3.6/site-packages/urllib3/util/ssl_.py", line 329, in ssl_wrap_socket
    return context.wrap_socket(sock, server_hostname=server_hostname)
  File "/Users/l2k/.pyenv/versions/3.6.1/lib/python3.6/ssl.py", line 401, in wrap_socket
    _context=self, _session=session)
  File "/Users/l2k/.pyenv/versions/3.6.1/lib/python3.6/ssl.py", line 808, in __init__
    self.do_handshake()
  File "/Users/l2k/.pyenv/versions/3.6.1/lib/python3.6/ssl.py", line 1061, in do_handshake
    self._sslobj.do_handshake()
  File "/Users/l2k/.pyenv/versions/3.6.1/lib/python3.6/ssl.py", line 683, in do_handshake
    self._sslobj.do_handshake()
ConnectionResetError: [Errno 54] Connection reset by peer

During handling of the above exception, another exception occurred:

Traceback (most recent call last):
  File "/Users/l2k/.pyenv/versions/3.6.1/envs/wandb-3.6.1/lib/python3.6/site-packages/requests/adapters.py", line 440, in send
    timeout=timeout
  File "/Users/l2k/.pyenv/versions/3.6.1/envs/wandb-3.6.1/lib/python3.6/site-packages/urllib3/connectionpool.py", line 639, in urlopen
    _stacktrace=sys.exc_info()[2])
  File "/Users/l2k/.pyenv/versions/3.6.1/envs/wandb-3.6.1/lib/python3.6/site-packages/urllib3/util/retry.py", line 357, in increment
    raise six.reraise(type(error), error, _stacktrace)
  File "/Users/l2k/.pyenv/versions/3.6.1/envs/wandb-3.6.1/lib/python3.6/site-packages/urllib3/packages/six.py", line 685, in reraise
    raise value.with_traceback(tb)
  File "/Users/l2k/.pyenv/versions/3.6.1/envs/wandb-3.6.1/lib/python3.6/site-packages/urllib3/connectionpool.py", line 601, in urlopen
    chunked=chunked)
  File "/Users/l2k/.pyenv/versions/3.6.1/envs/wandb-3.6.1/lib/python3.6/site-packages/urllib3/connectionpool.py", line 346, in _make_request
    self._validate_conn(conn)
  File "/Users/l2k/.pyenv/versions/3.6.1/envs/wandb-3.6.1/lib/python3.6/site-packages/urllib3/connectionpool.py", line 850, in _validate_conn
    conn.connect()
  File "/Users/l2k/.pyenv/versions/3.6.1/envs/wandb-3.6.1/lib/python3.6/site-packages/urllib3/connection.py", line 326, in connect
    ssl_context=context)
  File "/Users/l2k/.pyenv/versions/3.6.1/envs/wandb-3.6.1/lib/python3.6/site-packages/urllib3/util/ssl_.py", line 329, in ssl_wrap_socket
    return context.wrap_socket(sock, server_hostname=server_hostname)
  File "/Users/l2k/.pyenv/versions/3.6.1/lib/python3.6/ssl.py", line 401, in wrap_socket
    _context=self, _session=session)
  File "/Users/l2k/.pyenv/versions/3.6.1/lib/python3.6/ssl.py", line 808, in __init__
    self.do_handshake()
  File "/Users/l2k/.pyenv/versions/3.6.1/lib/python3.6/ssl.py", line 1061, in do_handshake
    self._sslobj.do_handshake()
  File "/Users/l2k/.pyenv/versions/3.6.1/lib/python3.6/ssl.py", line 683, in do_handshake
    self._sslobj.do_handshake()
urllib3.exceptions.ProtocolError: ('Connection aborted.', ConnectionResetError(54, 'Connection reset by peer'))

During handling of the above exception, another exception occurred:

Traceback (most recent call last):
  File "/Users/l2k/client/wandb/api.py", line 682, in upload_file
    url, data=progress, headers=extra_headers)
  File "/Users/l2k/.pyenv/versions/3.6.1/envs/wandb-3.6.1/lib/python3.6/site-packages/requests/api.py", line 126, in put
    return request('put', url, data=data, **kwargs)
  File "/Users/l2k/.pyenv/versions/3.6.1/envs/wandb-3.6.1/lib/python3.6/site-packages/requests/api.py", line 58, in request
    return session.request(method=method, url=url, **kwargs)
  File "/Users/l2k/.pyenv/versions/3.6.1/envs/wandb-3.6.1/lib/python3.6/site-packages/requests/sessions.py", line 508, in request
    resp = self.send(prep, **send_kwargs)
  File "/Users/l2k/.pyenv/versions/3.6.1/envs/wandb-3.6.1/lib/python3.6/site-packages/requests/sessions.py", line 618, in send
    r = adapter.send(request, **kwargs)
  File "/Users/l2k/.pyenv/versions/3.6.1/envs/wandb-3.6.1/lib/python3.6/site-packages/requests/adapters.py", line 490, in send
    raise ConnectionError(err, request=request)
requests.exceptions.ConnectionError: ('Connection aborted.', ConnectionResetError(54, 'Connection reset by peer'))

During handling of the above exception, another exception occurred:

Traceback (most recent call last):
  File "/Users/l2k/client/wandb/api.py", line 73, in wrapper
    return func(*args, **kwargs)
  File "/Users/l2k/client/wandb/api.py", line 690, in upload_file
    completed = int(status.headers['Range'].split("-")[-1])
  File "/Users/l2k/.pyenv/versions/3.6.1/envs/wandb-3.6.1/lib/python3.6/site-packages/requests/structures.py", line 54, in __getitem__
    return self._store[key.lower()][1]
KeyError: 'range'

During handling of the above exception, another exception occurred:

Traceback (most recent call last):
  File "/Users/l2k/client/wandb/api.py", line 73, in wrapper
    return func(*args, **kwargs)
  File "/Users/l2k/client/wandb/api.py", line 877, in push
    file_info['url'], open_file, progress))
  File "/Users/l2k/client/wandb/api.py", line 99, in wrapper
    raise CommError(message)
wandb.api.CommError: 'range'

During handling of the above exception, another exception occurred:

Traceback (most recent call last):
  File "/Users/l2k/.pyenv/versions/3.6.1/lib/python3.6/threading.py", line 916, in _bootstrap_inner
    self.run()
  File "/Users/l2k/client/wandb/file_pusher.py", line 33, in run
    self._push_function(self.save_name, save_path)
  File "/Users/l2k/client/wandb/sync.py", line 191, in push_function
    progress=lambda _, total: self._stats.update_progress(path, total))
  File "/Users/l2k/client/wandb/api.py", line 99, in wrapper
    raise CommError(message)
wandb.api.CommError: 'range'
```

