TITLE:
Ugly errors when backend is failing

LABEL:
c:misc

STATE:
closed

BODY:
My local redis server died and when I ran something locally, here was the output to the terminal:

```bash
Traceback (most recent call last):
  File "/Users/vanpelt/Development/WandB/core/frontends/client/wandb/retry.py", line 79, in __call__
    result = self._call_fn(*args, **kwargs)
  File "/Users/vanpelt/.pyenv/versions/tensorflow-2.7/lib/python2.7/site-packages/gql/client.py", line 50, in execute
    result = self._get_result(document, *args, **kwargs)
  File "/Users/vanpelt/.pyenv/versions/tensorflow-2.7/lib/python2.7/site-packages/gql/client.py", line 73, in _get_result
    raise RetryError(retries_count, last_exception)
RetryError: Failed 1 retries: 400 Client Error: Bad Request for url: http://gql.test/graphql
Repeat: 0, Epoch: 1, accuracy: 0.35683675934
Repeat: 0, Epoch: 2, accuracy: 0.610605562693
Repeat: 0, Epoch: 3, accuracy: 0.144500147504
Pretty blue
Traceback (most recent call last):
  File "/Users/vanpelt/Development/WandB/core/frontends/client/wandb/retry.py", line 79, in __call__
    result = self._call_fn(*args, **kwargs)
  File "/Users/vanpelt/.pyenv/versions/tensorflow-2.7/lib/python2.7/site-packages/gql/client.py", line 50, in execute
    result = self._get_result(document, *args, **kwargs)
  File "/Users/vanpelt/.pyenv/versions/tensorflow-2.7/lib/python2.7/site-packages/gql/client.py", line 73, in _get_result
    raise RetryError(retries_count, last_exception)
RetryError: Failed 1 retries: 400 Client Error: Bad Request for url: http://gql.test/graphql
Repeat: 0, Epoch: 1, accuracy: 0.35683675934
Repeat: 0, Epoch: 2, accuracy: 0.610605562693
Repeat: 0, Epoch: 3, accuracy: 0.144500147504
Pretty blue
Traceback (most recent call last):
  File "/Users/vanpelt/Development/WandB/core/frontends/client/wandb/retry.py", line 79, in __call__
    result = self._call_fn(*args, **kwargs)
  File "/Users/vanpelt/.pyenv/versions/tensorflow-2.7/lib/python2.7/site-packages/gql/client.py", line 50, in execute
    result = self._get_result(document, *args, **kwargs)
  File "/Users/vanpelt/.pyenv/versions/tensorflow-2.7/lib/python2.7/site-packages/gql/client.py", line 73, in _get_result
    raise RetryError(retries_count, last_exception)
RetryError: Failed 1 retries: 400 Client Error: Bad Request for url: http://gql.test/graphql
Repeat: 0, Epoch: 4, accuracy: 0.10778700667
Repeat: 0, Epoch: 5, accuracy: 0.719535913481
Repeat: 0, Epoch: 6, accuracy: 0.0455859299644
Pretty blue
wandb network error (RetryError), entering retry loop. See wandb/debug.log for full traceback.
Traceback (most recent call last):
  File "/Users/vanpelt/Development/WandB/core/frontends/client/wandb/retry.py", line 79, in __call__
    result = self._call_fn(*args, **kwargs)
  File "/Users/vanpelt/.pyenv/versions/tensorflow-2.7/lib/python2.7/site-packages/gql/client.py", line 50, in execute
    result = self._get_result(document, *args, **kwargs)
  File "/Users/vanpelt/.pyenv/versions/tensorflow-2.7/lib/python2.7/site-packages/gql/client.py", line 73, in _get_result
    raise RetryError(retries_count, last_exception)
RetryError: Failed 1 retries: 400 Client Error: Bad Request for url: http://gql.test/graphql
Repeat: 0, Epoch: 7, accuracy: 0.120346332271
Someother stuff 7
Repeat: 0, Epoch: 8, accuracy: 0.82121719103
Found new best epoch, setting summary
Repeat: 0, Epoch: 9, accuracy: 0.0765244702333
Pretty blue

wandb: Program ended.
```

