TITLE:
Wandb never resume after network error resolved [CLI] 

LABEL:
cli

STATE:
closed

BODY:
**Description**
The wandb logging stopped due to the HTTPError (500 Server Error: Internal server error for url ...). However, the network error resolved and "resuming normal operation" was printed out. But the log aren't updated on the web app anymore.

**Wandb features**
I am using PyTorch Lightening, with "ddp" backend. I'm also running my model on a HPC cluster.


**Environment**
- OS: [Linux]
- Python Version: [eg. 3.8.3]


