TITLE:
[Feature] Add documentation to the wandb sweep page on gitbook-docs

LABEL:
feature_request

STATE:
closed

BODY:
**Is your feature request related to a problem? Please describe.**
I can't figure out how to use the `wandb sweep` cli tool to update a running sweep.

**Describe the solution you'd like**
I would like the documentation for `wandb sweep` to be filled out so that I can find out how to use the update function


**Describe alternatives you've considered**
I have tried to call the `wandb sweep <sweep_id> --`  but got an oblique error

`<sweep_id>` looks like `xk2thesj` (I changed a letter for privacy)

```
jsm81$ python3 -m wandb sweep <sweep_id> --update dim_latent_space=15
400 response executing GraphQL.
{"errors":[{"message":"name required for project query","path":["project"]}],"data":{"project":null}}
wandb: ERROR Error while calling W&B API: name required for project query (<Response [400]>)
Traceback (most recent call last):
  File "/home/home4/jsm81/.local/lib/python3.6/site-packages/wandb/apis/normalize.py", line 24, in wrapper
    return func(*args, **kwargs)
  File "/home/home4/jsm81/.local/lib/python3.6/site-packages/wandb/sdk/internal/internal_api.py", line 460, in sweep
    "specs": specs,
  File "/home/home4/jsm81/.local/lib/python3.6/site-packages/wandb/sdk/lib/retry.py", line 102, in __call__
    result = self._call_fn(*args, **kwargs)
  File "/home/home4/jsm81/.local/lib/python3.6/site-packages/wandb/sdk/internal/internal_api.py", line 133, in execute
    six.reraise(*sys.exc_info())
  File "/home/home4/jsm81/.local/lib/python3.6/site-packages/six.py", line 719, in reraise
    raise value
  File "/home/home4/jsm81/.local/lib/python3.6/site-packages/wandb/sdk/internal/internal_api.py", line 127, in execute
    return self.client.execute(*args, **kwargs)
  File "/home/home4/jsm81/.local/lib/python3.6/site-packages/wandb/vendor/gql-0.2.0/gql/client.py", line 52, in execute
    result = self._get_result(document, *args, **kwargs)
  File "/home/home4/jsm81/.local/lib/python3.6/site-packages/wandb/vendor/gql-0.2.0/gql/client.py", line 60, in _get_result
    return self.transport.execute(document, *args, **kwargs)
  File "/home/home4/jsm81/.local/lib/python3.6/site-packages/wandb/vendor/gql-0.2.0/gql/transport/requests.py", line 39, in execute
    request.raise_for_status()
  File "/usr/local/lib/python3.6/dist-packages/requests/models.py", line 941, in raise_for_status
    raise HTTPError(http_error_msg, response=self)
requests.exceptions.HTTPError: 400 Client Error: Bad Request for url: https://api.wandb.ai/graphql

During handling of the above exception, another exception occurred:

Traceback (most recent call last):
  File "/home/home4/jsm81/.local/lib/python3.6/site-packages/wandb/cli/cli.py", line 89, in wrapper
    return func(*args, **kwargs)
  File "/home/home4/jsm81/.local/lib/python3.6/site-packages/wandb/cli/cli.py", line 753, in sweep
    found = api.sweep(sweep_id, "{}", entity=entity, project=project)
  File "/home/home4/jsm81/.local/lib/python3.6/site-packages/wandb/apis/internal.py", line 97, in sweep
    return self.api.sweep(*args, **kwargs)
  File "/home/home4/jsm81/.local/lib/python3.6/site-packages/wandb/apis/normalize.py", line 26, in wrapper
    raise CommError(err.response, err)
wandb.errors.CommError: <Response [400]>

Error: <Response [400]>
```

**Additional context**

This is the web page i'm talking about: 
https://gitbook-docs.wandb.ai/ref/cli/wandb-sweep

