TITLE:
[CLI]: Calling wandb.init() on slow storage triggers OSErrors

LABEL:
cli

STATE:
closed

BODY:
### Describe the bug

<!--- Description of the issue below  -->
Initializing Weights and Biases produces an `OSError` if the storage is too slow to create the file.

On a SSD the code below works just fine. But on a very slow network storage ([Quobyte](https://www.quobyte.com/)) it seems a thread initialized in `wandb.init()` that is looking for a file called `wandb-metadata.json` which is not available yet. I think it might be related to the fact that it takes some time for metadata to propagate to all nodes in Quobyte, but a) I am not sure about that and b) the `init()` call and the error happen on the same machine.

<!--- A minimal code snippet between the quotes below  -->
```python
import wandb
wandb.init()
```

<!--- A full traceback of the exception in the quotes below -->
This produces the following traceback:
```shell
Exception in thread Thread-16 (_thread_body):
Traceback (most recent call last):
  File "/mnt/miniconda3/envs/envname/lib/python3.10/site-packages/wandb/filesync/step_checksum.py", line 83, in _thread_body
    shutil.copy2(req.path, path)
  File "/mnt/miniconda3/envs/envname/lib/python3.10/shutil.py", line 435, in copy2
    copystat(src, dst, follow_symlinks=follow_symlinks)
  File "/mnt/miniconda3/envs/envname/lib/python3.10/shutil.py", line 378, in copystat
    _copyxattr(src, dst, follow_symlinks=follow)
  File "/mnt/miniconda3/envs/envname/lib/python3.10/shutil.py", line 320, in _copyxattr
OSError: [Errno 5] Input/output error: 'wandb/run-20220817_182503-1bv74ap5/files/wandb-metadata.json'

During handling of the above exception, another exception occurred:

Traceback (most recent call last):
  File "/mnt/miniconda3/envs/envname/lib/python3.10/threading.py", line 1016, in _bootstrap_inner
    self.run()
  File "/mnt/miniconda3/envs/envname/lib/python3.10/threading.py", line 953, in run
    self._target(*self._args, **self._kwargs)
  File "/mnt/miniconda3/envs/envname/lib/python3.10/site-packages/wandb/filesync/step_checksum.py", line 86, in _thread_body
    shutil.copy2(req.path, path)
  File "/mnt/miniconda3/envs/envname/lib/python3.10/shutil.py", line 435, in copy2
    copystat(src, dst, follow_symlinks=follow_symlinks)
  File "/mnt/miniconda3/envs/envname/lib/python3.10/shutil.py", line 378, in copystat
    _copyxattr(src, dst, follow_symlinks=follow)
  File "/mnt/miniconda3/envs/envname/lib/python3.10/shutil.py", line 320, in _copyxattr
    names = os.listxattr(src, follow_symlinks=follow_symlinks)
OSError: [Errno 5] Input/output error: '/wandb/run-20220817_182503-1bv74ap5/files/wandb-metadata.json'
```

As this is only an error in a thread the program continues normally (I suppose) and the file `wandb-metadata.json` eventually appears on the disk.
I also tried the `fork` setting but that did not make a difference.

### Additional Files

_No response_

### Environment

WandB version: 0.13.1

OS: Ubuntu 18.04.6 LTS

Python version: 3.10.5


### Additional Context

_No response_

