TITLE:
[CLI]: Error while calling W&B API: internal database error (<Response [500]>)

LABEL:
cli

STATE:
closed

BODY:
### Describe the bug

<!--- Description of the issue below  -->
Wandb logs stop getting synced after training starts.

<!--- A minimal code snippet between the quotes below  -->
```python
wandb_logger = pl.loggers.WandbLogger(project="etok", save_dir='...')
wandb.run.name = f"{DATASET} {'-'.join(langs)} {model_type}{model.config.num_prefix} {decoder} {batch_size}bs {block_size}bl {'-'.join(wandb.run.name.split('-')[:2])}"
trainer = Trainer(.... logger=wandb_logger, ....)
trainer.fit(model, train_loader, val_loader)
```
Error:
<!--- A full traceback of the exception in the quotes below -->
```shell
Epoch 0:   1%|▋                                                                                | 44/4943 [00:11<21:31,  3.79it/s, loss=7.11, v_num=z34s]
wandb: ERROR Error while calling W&B API: internal database error (<Response [500]>)
Epoch 0:   1%|▉                                                                                | 60/4943 [00:14<20:16,  4.01it/s, loss=6.37, v_num=z34s]
wandb: ERROR Error while calling W&B API: internal database error (<Response [500]>)
Epoch 0:   2%|█▎                                                                               | 83/4943 [00:19<18:58,  4.27it/s, loss=6.26, v_num=z34s]
wandb: ERROR Error while calling W&B API: internal database error (<Response [500]>)
```


### Additional Files

_No response_

### Environment

WandB version: 0.13.3

OS: Linux

Python version: 3.9.13

Versions of relevant libraries: torch 1.12.1+cu102


### Additional Context

_No response_

