TITLE:
W&B process failed to launch, see: wandb\debug.log

LABEL:
bug,stale

STATE:
closed

BODY:
`wandb --version && python --version && uname`

* Weights and Biases version: 0.9.0
* Python version:3.7
* Operating System:win10

### Description

I run my program in pycharm 2020 and init wandb with this code:`wandb.init(project="future_trade_test", sync_tensorboard=True)`,
and it show this error:
```wandb: Tracking run with wandb version 0.9.0
Traceback (most recent call last):
  File "C:\Users\zkx74\Anaconda3\lib\site-packages\wandb\internal_cli.py", line 106, in <module>
    main()
  File "C:\Users\zkx74\Anaconda3\lib\site-packages\wandb\internal_cli.py", line 98, in main
    headless(args)
  File "C:\Users\zkx74\Anaconda3\lib\site-packages\wandb\internal_cli.py", line 54, in headless
    util.sentry_reraise(e)
  File "C:\Users\zkx74\Anaconda3\lib\site-packages\wandb\util.py", line 94, in sentry_reraise
    six.reraise(type(exc), exc, sys.exc_info()[2])
  File "C:\Users\zkx74\Anaconda3\lib\site-packages\six.py", line 696, in reraise
    raise value
  File "C:\Users\zkx74\Anaconda3\lib\site-packages\wandb\internal_cli.py", line 52, in headless
    user_process_pid, stdout_master_fd, stderr_master_fd)
  File "C:\Users\zkx74\Anaconda3\lib\site-packages\wandb\run_manager.py", line 1140, in wrap_existing_process
    stderr_read_file = os.fdopen(stderr_read_fd, 'rb')
  File "C:\Users\zkx74\Anaconda3\lib\os.py", line 1027, in fdopen
    return io.open(fd, *args, **kwargs)
OSError: [WinError 6] 句柄无效。
wandb: ERROR W&B process (PID 20148) did not respond
wandb: ERROR W&B process failed to launch, see: wandb\debug.log
Traceback (most recent call last):
  File "E:/PycharmProjects/test_parallel3/run_paraellel3.py", line 14, in <module>
    wandb.init(project="future_trade_test", sync_tensorboard=True)
  File "C:\Users\zkx74\Anaconda3\lib\site-packages\wandb\__init__.py", line 1123, in init
    _init_headless(run)
  File "C:\Users\zkx74\Anaconda3\lib\site-packages\wandb\__init__.py", line 312, in _init_headless
    "W&B process failed to launch, see: {}".format(path))
wandb.run_manager.LaunchError: W&B process failed to launch, see: wandb\debug.log
```

The wired thing is if I run it with debug mode, wandb init normally. And I can also run another project with wandb normally.
The project which have this problem is copied from my friend who is also using Wandb, I guess this may have some connections with the bug?

Here is my debug.log:
```2020-06-08 17:00:40,866 DEBUG   MainThread:20148 [wandb_config.py:_load_defaults():133] no defaults not found in config-defaults.yaml
2020-06-08 17:00:42,080 DEBUG   MainThread:20148 [git_repo.py:repo():30] git repository is invalid
2020-06-08 17:00:42,163 DEBUG   MainThread:20148 [run_manager.py:__init__():547] Initialized sync for future_trade_test/uip8waey
```
### What I Did

```
Paste the command(s) you ran and the output.
If there was a crash, please include the traceback here.
```


