TITLE:
[CLI] init fails

LABEL:
cli

STATE:
closed

BODY:
`wandb --version && python --version && uname`
wandb, version 0.10.15
Python 3.8.7
Linux

**Description**
Just trying to simply run wandb.init().  
I created account and copied API_KEY.
I install wandb and login from shell:
```
pip install --upgrade wandb
wandb login <API_KEY>
```
Then run python script:
```
import wandb
wandb.init(project="test")
```
And I keep getting this error.  I've tried repeatedly deleting .netrc file.... does not help....
```
Traceback (most recent call last):
  File "/home/david/code/repo/ai2/test/venv/lib/python3.8/site-packages/wandb/apis/normalize.py", line 24, in wrapper
    return func(*args, **kwargs)
  File "/home/david/code/repo/ai2/test/venv/lib/python3.8/site-packages/wandb/sdk/internal/internal_api.py", line 382, in viewer
    res = self.gql(query)
  File "/home/david/code/repo/ai2/test/venv/lib/python3.8/site-packages/wandb/old/retry.py", line 96, in __call__
    result = self._call_fn(*args, **kwargs)
  File "/home/david/code/repo/ai2/test/venv/lib/python3.8/site-packages/wandb/sdk/internal/internal_api.py", line 131, in execute
    return self.client.execute(*args, **kwargs)
  File "/home/david/code/repo/ai2/test/venv/lib/python3.8/site-packages/wandb/vendor/gql-0.2.0/gql/client.py", line 52, in execute
    result = self._get_result(document, *args, **kwargs)
  File "/home/david/code/repo/ai2/test/venv/lib/python3.8/site-packages/wandb/vendor/gql-0.2.0/gql/client.py", line 60, in _get_result
    return self.transport.execute(document, *args, **kwargs)
  File "/home/david/code/repo/ai2/test/venv/lib/python3.8/site-packages/wandb/vendor/gql-0.2.0/gql/transport/requests.py", line 41, in execute
    result = request.json()
  File "/home/david/code/repo/ai2/test/venv/lib/python3.8/site-packages/requests/models.py", line 900, in json
    return complexjson.loads(self.text, **kwargs)
  File "/usr/lib/python3.8/json/__init__.py", line 357, in loads
    return _default_decoder.decode(s)
  File "/usr/lib/python3.8/json/decoder.py", line 337, in decode
    obj, end = self.raw_decode(s, idx=_w(s, 0).end())
  File "/usr/lib/python3.8/json/decoder.py", line 355, in raw_decode
    raise JSONDecodeError("Expecting value", s, err.value) from None
json.decoder.JSONDecodeError: Expecting value: line 1 column 1 (char 0)

During handling of the above exception, another exception occurred:

Traceback (most recent call last):
  File "/home/david/code/repo/ai2/test/venv/lib/python3.8/site-packages/wandb/cli/cli.py", line 94, in wrapper
    return func(*args, **kwargs)
  File "/home/david/code/repo/ai2/test/venv/lib/python3.8/site-packages/wandb/cli/cli.py", line 331, in init
    viewer = api.viewer()
  File "/home/david/code/repo/ai2/test/venv/lib/python3.8/site-packages/wandb/apis/internal.py", line 45, in viewer
    return self.api.viewer()
  File "/home/david/code/repo/ai2/test/venv/lib/python3.8/site-packages/wandb/apis/normalize.py", line 62, in wrapper
    six.reraise(CommError, CommError(message, err), sys.exc_info()[2])
  File "/home/david/code/repo/ai2/test/venv/lib/python3.8/site-packages/six.py", line 702, in reraise
    raise value.with_traceback(tb)
  File "/home/david/code/repo/ai2/test/venv/lib/python3.8/site-packages/wandb/apis/normalize.py", line 24, in wrapper
    return func(*args, **kwargs)
  File "/home/david/code/repo/ai2/test/venv/lib/python3.8/site-packages/wandb/sdk/internal/internal_api.py", line 382, in viewer
    res = self.gql(query)
  File "/home/david/code/repo/ai2/test/venv/lib/python3.8/site-packages/wandb/old/retry.py", line 96, in __call__
    result = self._call_fn(*args, **kwargs)
  File "/home/david/code/repo/ai2/test/venv/lib/python3.8/site-packages/wandb/sdk/internal/internal_api.py", line 131, in execute
    return self.client.execute(*args, **kwargs)
  File "/home/david/code/repo/ai2/test/venv/lib/python3.8/site-packages/wandb/vendor/gql-0.2.0/gql/client.py", line 52, in execute
    result = self._get_result(document, *args, **kwargs)
  File "/home/david/code/repo/ai2/test/venv/lib/python3.8/site-packages/wandb/vendor/gql-0.2.0/gql/client.py", line 60, in _get_result
    return self.transport.execute(document, *args, **kwargs)
  File "/home/david/code/repo/ai2/test/venv/lib/python3.8/site-packages/wandb/vendor/gql-0.2.0/gql/transport/requests.py", line 41, in execute
    result = request.json()
  File "/home/david/code/repo/ai2/test/venv/lib/python3.8/site-packages/requests/models.py", line 900, in json
    return complexjson.loads(self.text, **kwargs)
  File "/usr/lib/python3.8/json/__init__.py", line 357, in loads
    return _default_decoder.decode(s)
  File "/usr/lib/python3.8/json/decoder.py", line 337, in decode
    obj, end = self.raw_decode(s, idx=_w(s, 0).end())
  File "/usr/lib/python3.8/json/decoder.py", line 355, in raw_decode
    raise JSONDecodeError("Expecting value", s, err.value) from None
wandb.errors.error.CommError: Expecting value: line 1 column 1 (char 0)
```


