TITLE:
[Q] How to download artifact model from a run ID using API

LABEL:
c:misc

STATE:
closed

BODY:
Hi,

I've used the API to find the run id of my best run, and want to download its associated model artifact. How can I do this? 

I've seen ways to use the artifact API to download artifacts, but need to download the best model, and therefore need to iterate through my runs to find the best one. 

Here's the run metadata:
```
Best Run:
- Name: 2021-12-07_11-19-01_NetVLAD++_Essential
- ID: k3xyplvz
- test_metric.max: 0.4192
- Model Filename: 2021-12-07_11-19-01_NetVLAD++_Essential.pth.tar
```

My code structure:
```
api = wandb.Api()

runs = api.runs(
        path="{}/{}".format(wandb_username, project_name),
        order="-summary_metrics.test_metric.max"
    )

# Logic to find best run 

best_run = api.run(path="{}/{}/{}".format(wandb_username, project_name, best_run_id))
best_model = best_run.file(best_model_name).download()
```

Gives me this error:
```
Traceback (most recent call last):
  File "/home/wilsonchan/anaconda3/envs/AceOne-CALF/lib/python3.8/site-packages/wandb/sdk/lib/retry.py", line 102, in __call__
    result = self._call_fn(*args, **kwargs)
  File "/home/wilsonchan/anaconda3/envs/AceOne-CALF/lib/python3.8/site-packages/wandb/apis/public.py", line 2384, in download
    util.download_file_from_url(path, self.url, Api().api_key)
  File "/home/wilsonchan/anaconda3/envs/AceOne-CALF/lib/python3.8/site-packages/wandb/util.py", line 1130, in download_file_from_url

    response.raise_for_status()
  File "/home/wilsonchan/anaconda3/envs/AceOne-CALF/lib/python3.8/site-packages/requests/models.py", line 953, in raise_for_status
    raise HTTPError(http_error_msg, response=self)
requests.exceptions.HTTPError: 404 Client Error: Not Found for url: https://api.wandb.ai/files/wilan/Automatic-Highlight-Generation/k3xyplvz/2021-12-07_11-19-01_NetVLAD++_Essenti
al.pth.tar

During handling of the above exception, another exception occurred:

Traceback (most recent call last):
  File "/home/wilsonchan/anaconda3/envs/AceOne-CALF/lib/python3.8/site-packages/wandb/apis/normalize.py", line 24, in wrapper
    return func(*args, **kwargs)
  File "/home/wilsonchan/anaconda3/envs/AceOne-CALF/lib/python3.8/site-packages/wandb/sdk/lib/retry.py", line 159, in wrapped_fn
    return retrier(*args, **kargs)
  File "/home/wilsonchan/anaconda3/envs/AceOne-CALF/lib/python3.8/site-packages/wandb/sdk/lib/retry.py", line 118, in __call__
    if not check_retry_fn(e):
  File "/home/wilsonchan/anaconda3/envs/AceOne-CALF/lib/python3.8/site-packages/wandb/util.py", line 821, in no_retry_auth
    raise CommError("Permission denied, ask the project owner to grant you access")
wandb.errors.CommError: Permission denied, ask the project owner to grant you access

During handling of the above exception, another exception occurred:

Traceback (most recent call last):
  File "Automatic-Highlight-Generation/create_highlight_videos.py", line 47, in <module>
    download_best_model(tag_name=initial_configs.model_name,
  File "Automatic-Highlight-Generation/create_highlight_videos.py", line 42, in download_best_model
    best_model = best_run.file(best_model_name).download()
  File "/home/wilsonchan/anaconda3/envs/AceOne-CALF/lib/python3.8/site-packages/wandb/apis/normalize.py", line 62, in wrapper
    six.reraise(CommError, CommError(message, err), sys.exc_info()[2])
  File "/home/wilsonchan/anaconda3/envs/AceOne-CALF/lib/python3.8/site-packages/six.py", line 718, in reraise
    raise value.with_traceback(tb)
  File "/home/wilsonchan/anaconda3/envs/AceOne-CALF/lib/python3.8/site-packages/wandb/apis/normalize.py", line 24, in wrapper
    return func(*args, **kwargs)
  File "/home/wilsonchan/anaconda3/envs/AceOne-CALF/lib/python3.8/site-packages/wandb/sdk/lib/retry.py", line 159, in wrapped_fn
    return retrier(*args, **kargs)
  File "/home/wilsonchan/anaconda3/envs/AceOne-CALF/lib/python3.8/site-packages/wandb/sdk/lib/retry.py", line 118, in __call__
    if not check_retry_fn(e):
  File "/home/wilsonchan/anaconda3/envs/AceOne-CALF/lib/python3.8/site-packages/wandb/util.py", line 821, in no_retry_auth
    raise CommError("Permission denied, ask the project owner to grant you access")
wandb.errors.CommError: Permission denied, ask the project owner to grant you access
```

